Workbook

Sheet Executive Dashboard
A1: LOAN PORTFOLIO EXECUTIVE DASHBOARD
A4: Total Applications | D4: Approval Rate | G4: Avg Applicant Income | J4: Avg Loan Amount
A5: 614 | D5: 0.68729642 | G5: 5403.4593 | J5: 146.41216
A20: Outcome | B20: Applications | E20: Property Area | F20: Approval Rate | I20: Credit History | J20: Approval Rate
A21: Approved | B21: 422 | E21: Rural | F21: 0.61452514 | I21: 0 | J21: 0.078651685
A22: Rejected | B22: 192 | E22: Semiurban | F22: 0.76824034 | I22: 1 | J22: 0.79578947
E23: Urban | F23: 0.65841584 | I23: Missing | J23: 0.74
G24: Management Observations
G25: • Credit history is the strongest observed separator of application decisions.
G26: • Semiurban has the highest observed approval rate.
G27: • Rejection is not evidence of default.
G28: • No date fields: trend analysis unavailable.
G29: • Income and loan units are undocumented.

Sheet data_bank_loan
A1: Loan_ID | B1: Gender | C1: Married | D1: Dependents | E1: Education | F1: Self_Employed | G1: ApplicantIncome | H1: CoapplicantIncome | I1: LoanAmount | J1: Loan_Amount_Term | K1: Credit_History | L1: Property_Area | M1: Loan_Status | N1: Risk_Category
A2: LP001002 | B2: Male | C2: No | D2: 0 | E2: Graduate | F2: No | G2: 5849 | H2: 0 | J2: 360 | K2: 1 | L2: Urban | M2: Y | N2: =IF(AND(K2=1,M2="Y"),"Lower Risk",IF(AND(K2=0,M2="N"),"High Risk","Medium Risk"))
A3: LP001003 | B3: Male | C3: Yes | D3: 1 | E3: Graduate | F3: No | G3: 4583 | H3: 1508 | I3: 128 | J3: 360 | K3: 1 | L3: Rural | M3: N | N3: =IF(AND(K3=1,M3="Y"),"Lower Risk",IF(AND(K3=0,M3="N"),"High Risk","Medium Risk"))
A4: LP001005 | B4: Male | C4: Yes | D4: 0 | E4: Graduate | F4: Yes | G4: 3000 | H4: 0 | I4: 66 | J4: 360 | K4: 1 | L4: Urban | M4: Y | N4: =IF(AND(K4=1,M4="Y"),"Lower Risk",IF(AND(K4=0,M4="N"),"High Risk","Medium Risk"))
A5: LP001006 | B5: Male | C5: Yes | D5: 0 | E5: Not Graduate | F5: No | G5: 2583 | H5: 2358 | I5: 120 | J5: 360 | K5: 1 | L5: Urban | M5: Y | N5: =IF(AND(K5=1,M5="Y"),"Lower Risk",IF(AND(K5=0,M5="N"),"High Risk","Medium Risk"))
A6: LP001008 | B6: Male | C6: No | D6: 0 | E6: Graduate | F6: No | G6: 6000 | H6: 0 | I6: 141 | J6: 360 | K6: 1 | L6: Urban | M6: Y | N6: =IF(AND(K6=1,M6="Y"),"Lower Risk",IF(AND(K6=0,M6="N"),"High Risk","Medium Risk"))
A7: LP001011 | B7: Male | C7: Yes | D7: 2 | E7: Graduate | F7: Yes | G7: 5417 | H7: 4196 | I7: 267 | J7: 360 | K7: 1 | L7: Urban | M7: Y | N7: =IF(AND(K7=1,M7="Y"),"Lower Risk",IF(AND(K7=0,M7="N"),"High Risk","Medium Risk"))
A8: LP001013 | B8: Male | C8: Yes | D8: 0 | E8: Not Graduate | F8: No | G8: 2333 | H8: 1516 | I8: 95 | J8: 360 | K8: 1 | L8: Urban | M8: Y | N8: =IF(AND(K8=1,M8="Y"),"Lower Risk",IF(AND(K8=0,M8="N"),"High Risk","Medium Risk"))
A9: LP001014 | B9: Male | C9: Yes | D9: 3+ | E9: Graduate | F9: No | G9: 3036 | H9: 2504 | I9: 158 | J9: 360 | K9: 0 | L9: Semiurban | M9: N | N9: =IF(AND(K9=1,M9="Y"),"Lower Risk",IF(AND(K9=0,M9="N"),"High Risk","Medium Risk"))
A10: LP001018 | B10: Male | C10: Yes | D10: 2 | E10: Graduate | F10: No | G10: 4006 | H10: 1526 | I10: 168 | J10: 360 | K10: 1 | L10: Urban | M10: Y | N10: =IF(AND(K10=1,M10="Y"),"Lower Risk",IF(AND(K10=0,M10="N"),"High Risk","Medium Risk"))
A11: LP001020 | B11: Male | C11: Yes | D11: 1 | E11: Graduate | F11: No | G11: 12841 | H11: 10968 | I11: 349 | J11: 360 | K11: 1 | L11: Semiurban | M11: N | N11: =IF(AND(K11=1,M11="Y"),"Lower Risk",IF(AND(K11=0,M11="N"),"High Risk","Medium Risk"))
A12: LP001024 | B12: Male | C12: Yes | D12: 2 | E12: Graduate | F12: No | G12: 3200 | H12: 700 | I12: 70 | J12: 360 | K12: 1 | L12: Urban | M12: Y | N12: =IF(AND(K12=1,M12="Y"),"Lower Risk",IF(AND(K12=0,M12="N"),"High Risk","Medium Risk"))
A13: LP001027 | B13: Male | C13: Yes | D13: 2 | E13: Graduate | G13: 2500 | H13: 1840 | I13: 109 | J13: 360 | K13: 1 | L13: Urban | M13: Y | N13: =IF(AND(K13=1,M13="Y"),"Lower Risk",IF(AND(K13=0,M13="N"),"High Risk","Medium Risk"))
A14: LP001028 | B14: Male | C14: Yes | D14: 2 | E14: Graduate | F14: No | G14: 3073 | H14: 8106 | I14: 200 | J14: 360 | K14: 1 | L14: Urban | M14: Y | N14: =IF(AND(K14=1,M14="Y"),"Lower Risk",IF(AND(K14=0,M14="N"),"High Risk","Medium Risk"))
A15: LP001029 | B15: Male | C15: No | D15: 0 | E15: Graduate | F15: No | G15: 1853 | H15: 2840 | I15: 114 | J15: 360 | K15: 1 | L15: Rural | M15: N | N15: =IF(AND(K15=1,M15="Y"),"Lower Risk",IF(AND(K15=0,M15="N"),"High Risk","Medium Risk"))
A16: LP001030 | B16: Male | C16: Yes | D16: 2 | E16: Graduate | F16: No | G16: 1299 | H16: 1086 | I16: 17 | J16: 120 | K16: 1 | L16: Urban | M16: Y | N16: =IF(AND(K16=1,M16="Y"),"Lower Risk",IF(AND(K16=0,M16="N"),"High Risk","Medium Risk"))
A17: LP001032 | B17: Male | C17: No | D17: 0 | E17: Graduate | F17: No | G17: 4950 | H17: 0 | I17: 125 | J17: 360 | K17: 1 | L17: Urban | M17: Y | N17: =IF(AND(K17=1,M17="Y"),"Lower Risk",IF(AND(K17=0,M17="N"),"High Risk","Medium Risk"))
A18: LP001034 | B18: Male | C18: No | D18: 1 | E18: Not Graduate | F18: No | G18: 3596 | H18: 0 | I18: 100 | J18: 240 | L18: Urban | M18: Y | N18: =IF(AND(K18=1,M18="Y"),"Lower Risk",IF(AND(K18=0,M18="N"),"High Risk","Medium Risk"))
A19: LP001036 | B19: Female | C19: No | D19: 0 | E19: Graduate | F19: No | G19: 3510 | H19: 0 | I19: 76 | J19: 360 | K19: 0 | L19: Urban | M19: N | N19: =IF(AND(K19=1,M19="Y"),"Lower Risk",IF(AND(K19=0,M19="N"),"High Risk","Medium Risk"))
A20: LP001038 | B20: Male | C20: Yes | D20: 0 | E20: Not Graduate | F20: No | G20: 4887 | H20: 0 | I20: 133 | J20: 360 | K20: 1 | L20: Rural | M20: N | N20: =IF(AND(K20=1,M20="Y"),"Lower Risk",IF(AND(K20=0,M20="N"),"High Risk","Medium Risk"))
A21: LP001041 | B21: Male | C21: Yes | D21: 0 | E21: Graduate | G21: 2600 | H21: 3500 | I21: 115 | K21: 1 | L21: Urban | M21: Y | N21: =IF(AND(K21=1,M21="Y"),"Lower Risk",IF(AND(K21=0,M21="N"),"High Risk","Medium Risk"))
A22: LP001043 | B22: Male | C22: Yes | D22: 0 | E22: Not Graduate | F22: No | G22: 7660 | H22: 0 | I22: 104 | J22: 360 | K22: 0 | L22: Urban | M22: N | N22: =IF(AND(K22=1,M22="Y"),"Lower Risk",IF(AND(K22=0,M22="N"),"High Risk","Medium Risk"))
A23: LP001046 | B23: Male | C23: Yes | D23: 1 | E23: Graduate | F23: No | G23: 5955 | H23: 5625 | I23: 315 | J23: 360 | K23: 1 | L23: Urban | M23: Y | N23: =IF(AND(K23=1,M23="Y"),"Lower Risk",IF(AND(K23=0,M23="N"),"High Risk","Medium Risk"))
A24: LP001047 | B24: Male | C24: Yes | D24: 0 | E24: Not Graduate | F24: No | G24: 2600 | H24: 1911 | I24: 116 | J24: 360 | K24: 0 | L24: Semiurban | M24: N | N24: =IF(AND(K24=1,M24="Y"),"Lower Risk",IF(AND(K24=0,M24="N"),"High Risk","Medium Risk"))
A25: LP001050 | C25: Yes | D25: 2 | E25: Not Graduate | F25: No | G25: 3365 | H25: 1917 | I25: 112 | J25: 360 | K25: 0 | L25: Rural | M25: N | N25: =IF(AND(K25=1,M25="Y"),"Lower Risk",IF(AND(K25=0,M25="N"),"High Risk","Medium Risk"))
A26: LP001052 | B26: Male | C26: Yes | D26: 1 | E26: Graduate | G26: 3717 | H26: 2925 | I26: 151 | J26: 360 | L26: Semiurban | M26: N | N26: =IF(AND(K26=1,M26="Y"),"Lower Risk",IF(AND(K26=0,M26="N"),"High Risk","Medium Risk"))
A27: LP001066 | B27: Male | C27: Yes | D27: 0 | E27: Graduate | F27: Yes | G27: 9560 | H27: 0 | I27: 191 | J27: 360 | K27: 1 | L27: Semiurban | M27: Y | N27: =IF(AND(K27=1,M27="Y"),"Lower Risk",IF(AND(K27=0,M27="N"),"High Risk","Medium Risk"))
A28: LP001068 | B28: Male | C28: Yes | D28: 0 | E28: Graduate | F28: No | G28: 2799 | H28: 2253 | I28: 122 | J28: 360 | K28: 1 | L28: Semiurban | M28: Y | N28: =IF(AND(K28=1,M28="Y"),"Lower Risk",IF(AND(K28=0,M28="N"),"High Risk","Medium Risk"))
A29: LP001073 | B29: Male | C29: Yes | D29: 2 | E29: Not Graduate | F29: No | G29: 4226 | H29: 1040 | I29: 110 | J29: 360 | K29: 1 | L29: Urban | M29: Y | N29: =IF(AND(K29=1,M29="Y"),"Lower Risk",IF(AND(K29=0,M29="N"),"High Risk","Medium Risk"))
A30: LP001086 | B30: Male | C30: No | D30: 0 | E30: Not Graduate | F30: No | G30: 1442 | H30: 0 | I30: 35 | J30: 360 | K30: 1 | L30: Urban | M30: N | N30: =IF(AND(K30=1,M30="Y"),"Lower Risk",IF(AND(K30=0,M30="N"),"High Risk","Medium Risk"))
A31: LP001087 | B31: Female | C31: No | D31: 2 | E31: Graduate | G31: 3750 | H31: 2083 | I31: 120 | J31: 360 | K31: 1 | L31: Semiurban | M31: Y | N31: =IF(AND(K31=1,M31="Y"),"Lower Risk",IF(AND(K31=0,M31="N"),"High Risk","Medium Risk"))
A32: LP001091 | B32: Male | C32: Yes | D32: 1 | E32: Graduate | G32: 4166 | H32: 3369 | I32: 201 | J32: 360 | L32: Urban | M32: N | N32: =IF(AND(K32=1,M32="Y"),"Lower Risk",IF(AND(K32=0,M32="N"),"High Risk","Medium Risk"))
A33: LP001095 | B33: Male | C33: No | D33: 0 | E33: Graduate | F33: No | G33: 3167 | H33: 0 | I33: 74 | J33: 360 | K33: 1 | L33: Urban | M33: N | N33: =IF(AND(K33=1,M33="Y"),"Lower Risk",IF(AND(K33=0,M33="N"),"High Risk","Medium Risk"))
A34: LP001097 | B34: Male | C34: No | D34: 1 | E34: Graduate | F34: Yes | G34: 4692 | H34: 0 | I34: 106 | J34: 360 | K34: 1 | L34: Rural | M34: N | N34: =IF(AND(K34=1,M34="Y"),"Lower Risk",IF(AND(K34=0,M34="N"),"High Risk","Medium Risk"))
A35: LP001098 | B35: Male | C35: Yes | D35: 0 | E35: Graduate | F35: No | G35: 3500 | H35: 1667 | I35: 114 | J35: 360 | K35: 1 | L35: Semiurban | M35: Y | N35: =IF(AND(K35=1,M35="Y"),"Lower Risk",IF(AND(K35=0,M35="N"),"High Risk","Medium Risk"))
A36: LP001100 | B36: Male | C36: No | D36: 3+ | E36: Graduate | F36: No | G36: 12500 | H36: 3000 | I36: 320 | J36: 360 | K36: 1 | L36: Rural | M36: N | N36: =IF(AND(K36=1,M36="Y"),"Lower Risk",IF(AND(K36=0,M36="N"),"High Risk","Medium Risk"))
A37: LP001106 | B37: Male | C37: Yes | D37: 0 | E37: Graduate | F37: No | G37: 2275 | H37: 2067 | J37: 360 | K37: 1 | L37: Urban | M37: Y | N37: =IF(AND(K37=1,M37="Y"),"Lower Risk",IF(AND(K37=0,M37="N"),"High Risk","Medium Risk"))
A38: LP001109 | B38: Male | C38: Yes | D38: 0 | E38: Graduate | F38: No | G38: 1828 | H38: 1330 | I38: 100 | K38: 0 | L38: Urban | M38: N | N38: =IF(AND(K38=1,M38="Y"),"Lower Risk",IF(AND(K38=0,M38="N"),"High Risk","Medium Risk"))
A39: LP001112 | B39: Female | C39: Yes | D39: 0 | E39: Graduate | F39: No | G39: 3667 | H39: 1459 | I39: 144 | J39: 360 | K39: 1 | L39: Semiurban | M39: Y | N39: =IF(AND(K39=1,M39="Y"),"Lower Risk",IF(AND(K39=0,M39="N"),"High Risk","Medium Risk"))
A40: LP001114 | B40: Male | C40: No | D40: 0 | E40: Graduate | F40: No | G40: 4166 | H40: 7210 | I40: 184 | J40: 360 | K40: 1 | L40: Urban | M40: Y | N40: =IF(AND(K40=1,M40="Y"),"Lower Risk",IF(AND(K40=0,M40="N"),"High Risk","Medium Risk"))
...

Sheet Bank Manager Dashboard
A1: Loan Portfolio Executive Dashboard
A3: Portfolio overview | 614 applications
B4: Total Applications | G4: Approval Rate | L4: Avg Applicant Income | Q4: Avg Loan Amount
B5: =COUNTA(data_bank_loan!$A$2:$A$615) | G5: =COUNTIF(data_bank_loan!$M$2:$M$615,"Y")/COUNTA(data_bank_loan!$A$2:$A$615) | L5: =AVERAGE(data_bank_loan!$G$2:$G$615) | Q5: =AVERAGE(data_bank_loan!$I$2:$I$615)
A47: Executive observations
A48: 1. Credit history is the strongest observed separator: approval is 79.6% for Credit_History = 1 versus 7.9% for Credit_History = 0.
A50: 2. Semiurban applications have the highest approval rate at 76.8%, compared with 65.8% Urban and 61.5% Rural.
A52: 3. Applicant income is right-skewed (median 3,812 vs average 5,403), while TotalIncome and LoanAmount have a moderate positive association (r = 0.62 across 592 complete records); these are associations, not causal effects.

Sheet Property Area Chart
A1: Loan Applicants by Property Area
A4: Property Area | B4: Applicant Count
A5: Semiurban | B5: =COUNTIF(data_bank_loan!$L$2:$L$615,A5)
A6: Urban | B6: =COUNTIF(data_bank_loan!$L$2:$L$615,A6)
A7: Rural | B7: =COUNTIF(data_bank_loan!$L$2:$L$615,A7)
F26: Approval Rate by Property Area
F28: Property Area | G28: Approved | H28: Total Applications | I28: Approval Rate
F29: Semiurban | G29: =COUNTIFS(data_bank_loan!$L$2:$L$615,F29,data_bank_loan!$M$2:$M$615,"Y") | H29: =COUNTIF(data_bank_loan!$L$2:$L$615,F29) | I29: =IFERROR(G29/H29,0)
F30: Urban | G30: =COUNTIFS(data_bank_loan!$L$2:$L$615,F30,data_bank_loan!$M$2:$M$615,"Y") | H30: =COUNTIF(data_bank_loan!$L$2:$L$615,F30) | I30: =IFERROR(G30/H30,0)
F31: Rural | G31: =COUNTIFS(data_bank_loan!$L$2:$L$615,F31,data_bank_loan!$M$2:$M$615,"Y") | H31: =COUNTIF(data_bank_loan!$L$2:$L$615,F31) | I31: =IFERROR(G31/H31,0)

Sheet Dashboard Data
A1: Credit History | B1: Approved | C1: Approval Rate | E1: Property Area | F1: Approved | G1: Approval Rate | I1: Total Income | J1: Loan Amount | K1: 0
A2: Good (1) | B2: =COUNTIFS(data_bank_loan!$K$2:$K$615,1,data_bank_loan!$M$2:$M$615,"Y") | C2: =B2/COUNTIF(data_bank_loan!$K$2:$K$615,1) | E2: Semiurban | F2: =COUNTIFS(data_bank_loan!$L$2:$L$615,E2,data_bank_loan!$M$2:$M$615,"Y") | G2: =F2/COUNTIF(data_bank_loan!$L$2:$L$615,E2) | I2: =data_bank_loan!G2+data_bank_loan!H2 | J2: =IF(data_bank_loan!I2="",NA(),data_bank_loan!I2) | K2: 1
A3: Missing | B3: =COUNTIFS(data_bank_loan!$K$2:$K$615,"",data_bank_loan!$M$2:$M$615,"Y") | C3: =B3/COUNTBLANK(data_bank_loan!$K$2:$K$615) | E3: Urban | F3: =COUNTIFS(data_bank_loan!$L$2:$L$615,E3,data_bank_loan!$M$2:$M$615,"Y") | G3: =F3/COUNTIF(data_bank_loan!$L$2:$L$615,E3) | I3: =data_bank_loan!G3+data_bank_loan!H3 | J3: =IF(data_bank_loan!I3="",NA(),data_bank_loan!I3)
A4: Poor (0) | B4: =COUNTIFS(data_bank_loan!$K$2:$K$615,0,data_bank_loan!$M$2:$M$615,"Y") | C4: =B4/COUNTIF(data_bank_loan!$K$2:$K$615,0) | E4: Rural | F4: =COUNTIFS(data_bank_loan!$L$2:$L$615,E4,data_bank_loan!$M$2:$M$615,"Y") | G4: =F4/COUNTIF(data_bank_loan!$L$2:$L$615,E4) | I4: =data_bank_loan!G4+data_bank_loan!H4 | J4: =IF(data_bank_loan!I4="",NA(),data_bank_loan!I4)
I5: =data_bank_loan!G5+data_bank_loan!H5 | J5: =IF(data_bank_loan!I5="",NA(),data_bank_loan!I5)
I6: =data_bank_loan!G6+data_bank_loan!H6 | J6: =IF(data_bank_loan!I6="",NA(),data_bank_loan!I6)
I7: =data_bank_loan!G7+data_bank_loan!H7 | J7: =IF(data_bank_loan!I7="",NA(),data_bank_loan!I7)
I8: =data_bank_loan!G8+data_bank_loan!H8 | J8: =IF(data_bank_loan!I8="",NA(),data_bank_loan!I8)
I9: =data_bank_loan!G9+data_bank_loan!H9 | J9: =IF(data_bank_loan!I9="",NA(),data_bank_loan!I9)
I10: =data_bank_loan!G10+data_bank_loan!H10 | J10: =IF(data_bank_loan!I10="",NA(),data_bank_loan!I10)
I11: =data_bank_loan!G11+data_bank_loan!H11 | J11: =IF(data_bank_loan!I11="",NA(),data_bank_loan!I11)
I12: =data_bank_loan!G12+data_bank_loan!H12 | J12: =IF(data_bank_loan!I12="",NA(),data_bank_loan!I12)
I13: =data_bank_loan!G13+data_bank_loan!H13 | J13: =IF(data_bank_loan!I13="",NA(),data_bank_loan!I13)
I14: =data_bank_loan!G14+data_bank_loan!H14 | J14: =IF(data_bank_loan!I14="",NA(),data_bank_loan!I14)
I15: =data_bank_loan!G15+data_bank_loan!H15 | J15: =IF(data_bank_loan!I15="",NA(),data_bank_loan!I15)
I16: =data_bank_loan!G16+data_bank_loan!H16 | J16: =IF(data_bank_loan!I16="",NA(),data_bank_loan!I16)
... I615: =data_bank_loan!G615+data_bank_loan!H615 | J615: =IF(data_bank_loan!I615="",NA(),data_bank_loan!I615)

Sheet Raw Data
A1: Loan_ID | B1: Gender | C1: Married | D1: Dependents | E1: Education | F1: Self_Employed | G1: ApplicantIncome | H1: CoapplicantIncome | I1: LoanAmount | J1: Loan_Amount_Term | K1: Credit_History | L1: Property_Area | M1: Loan_Status | N1: Risk_Category
A2: LP001002 | B2: Male | C2: No | D2: 0 | E2: Graduate | F2: No | G2: 5849 | H2: 0 | J2: 360 | K2: 1 | L2: Urban | M2: Y | N2: Lower Risk
A3: LP001003 | B3: Male | C3: Yes | D3: 1 | E3: Graduate | F3: No | G3: 4583 | H3: 1508 | I3: 128 | J3: 360 | K3: 1 | L3: Rural | M3: N | N3: Medium Risk
A4: LP001005 | B4: Male | C4: Yes | D4: 0 | E4: Graduate | F4: Yes | G4: 3000 | H4: 0 | I4: 66 | J4: 360 | K4: 1 | L4: Urban | M4: Y | N4: Lower Risk
A5: LP001006 | B5: Male | C5: Yes | D5: 0 | E5: Not Graduate | F5: No | G5: 2583 | H5: 2358 | I5: 120 | J5: 360 | K5: 1 | L5: Urban | M5: Y | N5: Lower Risk
A6: LP001008 | B6: Male | C6: No | D6: 0 | E6: Graduate | F6: No | G6: 6000 | H6: 0 | I6: 141 | J6: 360 | K6: 1 | L6: Urban | M6: Y | N6: Lower Risk
A7: LP001011 | B7: Male | C7: Yes | D7: 2 | E7: Graduate | F7: Yes | G7: 5417 | H7: 4196 | I7: 267 | J7: 360 | K7: 1 | L7: Urban | M7: Y | N7: Lower Risk
A8: LP001013 | B8: Male | C8: Yes | D8: 0 | E8: Not Graduate | F8: No | G8: 2333 | H8: 1516 | I8: 95 | J8: 360 | K8: 1 | L8: Urban | M8: Y | N8: Lower Risk
A9: LP001014 | B9: Male | C9: Yes | D9: 3+ | E9: Graduate | F9: No | G9: 3036 | H9: 2504 | I9: 158 | J9: 360 | K9: 0 | L9: Semiurban | M9: N | N9: High Risk
A10: LP001018 | B10: Male | C10: Yes | D10: 2 | E10: Graduate | F10: No | G10: 4006 | H10: 1526 | I10: 168 | J10: 360 | K10: 1 | L10: Urban | M10: Y | N10: Lower Risk
A11: LP001020 | B11: Male | C11: Yes | D11: 1 | E11: Graduate | F11: No | G11: 12841 | H11: 10968 | I11: 349 | J11: 360 | K11: 1 | L11: Semiurban | M11: N | N11: Medium Risk
A12: LP001024 | B12: Male | C12: Yes | D12: 2 | E12: Graduate | F12: No | G12: 3200 | H12: 700 | I12: 70 | J12: 360 | K12: 1 | L12: Urban | M12: Y | N12: Lower Risk
A13: LP001027 | B13: Male | C13: Yes | D13: 2 | E13: Graduate | G13: 2500 | H13: 1840 | I13: 109 | J13: 360 | K13: 1 | L13: Urban | M13: Y | N13: Lower Risk
A14: LP001028 | B14: Male | C14: Yes | D14: 2 | E14: Graduate | F14: No | G14: 3073 | H14: 8106 | I14: 200 | J14: 360 | K14: 1 | L14: Urban | M14: Y | N14: Lower Risk
A15: LP001029 | B15: Male | C15: No | D15: 0 | E15: Graduate | F15: No | G15: 1853 | H15: 2840 | I15: 114 | J15: 360 | K15: 1 | L15: Rural | M15: N | N15: Medium Risk
A16: LP001030 | B16: Male | C16: Yes | D16: 2 | E16: Graduate | F16: No | G16: 1299 | H16: 1086 | I16: 17 | J16: 120 | K16: 1 | L16: Urban | M16: Y | N16: Lower Risk
A17: LP001032 | B17: Male | C17: No | D17: 0 | E17: Graduate | F17: No | G17: 4950 | H17: 0 | I17: 125 | J17: 360 | K17: 1 | L17: Urban | M17: Y | N17: Lower Risk
A18: LP001034 | B18: Male | C18: No | D18: 1 | E18: Not Graduate | F18: No | G18: 3596 | H18: 0 | I18: 100 | J18: 240 | L18: Urban | M18: Y | N18: Medium Risk
A19: LP001036 | B19: Female | C19: No | D19: 0 | E19: Graduate | F19: No | G19: 3510 | H19: 0 | I19: 76 | J19: 360 | K19: 0 | L19: Urban | M19: N | N19: High Risk
A20: LP001038 | B20: Male | C20: Yes | D20: 0 | E20: Not Graduate | F20: No | G20: 4887 | H20: 0 | I20: 133 | J20: 360 | K20: 1 | L20: Rural | M20: N | N20: Medium Risk
A21: LP001041 | B21: Male | C21: Yes | D21: 0 | E21: Graduate | G21: 2600 | H21: 3500 | I21: 115 | K21: 1 | L21: Urban | M21: Y | N21: Lower Risk
A22: LP001043 | B22: Male | C22: Yes | D22: 0 | E22: Not Graduate | F22: No | G22: 7660 | H22: 0 | I22: 104 | J22: 360 | K22: 0 | L22: Urban | M22: N | N22: High Risk
A23: LP001046 | B23: Male | C23: Yes | D23: 1 | E23: Graduate | F23: No | G23: 5955 | H23: 5625 | I23: 315 | J23: 360 | K23: 1 | L23: Urban | M23: Y | N23: Lower Risk
A24: LP001047 | B24: Male | C24: Yes | D24: 0 | E24: Not Graduate | F24: No | G24: 2600 | H24: 1911 | I24: 116 | J24: 360 | K24: 0 | L24: Semiurban | M24: N | N24: High Risk
A25: LP001050 | C25: Yes | D25: 2 | E25: Not Graduate | F25: No | G25: 3365 | H25: 1917 | I25: 112 | J25: 360 | K25: 0 | L25: Rural | M25: N | N25: High Risk
A26: LP001052 | B26: Male | C26: Yes | D26: 1 | E26: Graduate | G26: 3717 | H26: 2925 | I26: 151 | J26: 360 | L26: Semiurban | M26: N | N26: High Risk
A27: LP001066 | B27: Male | C27: Yes | D27: 0 | E27: Graduate | F27: Yes | G27: 9560 | H27: 0 | I27: 191 | J27: 360 | K27: 1 | L27: Semiurban | M27: Y | N27: Lower Risk
A28: LP001068 | B28: Male | C28: Yes | D28: 0 | E28: Graduate | F28: No | G28: 2799 | H28: 2253 | I28: 122 | J28: 360 | K28: 1 | L28: Semiurban | M28: Y | N28: Lower Risk
A29: LP001073 | B29: Male | C29: Yes | D29: 2 | E29: Not Graduate | F29: No | G29: 4226 | H29: 1040 | I29: 110 | J29: 360 | K29: 1 | L29: Urban | M29: Y | N29: Lower Risk
A30: LP001086 | B30: Male | C30: No | D30: 0 | E30: Not Graduate | F30: No | G30: 1442 | H30: 0 | I30: 35 | J30: 360 | K30: 1 | L30: Urban | M30: N | N30: Medium Risk
A31: LP001087 | B31: Female | C31: No | D31: 2 | E31: Graduate | G31: 3750 | H31: 2083 | I31: 120 | J31: 360 | K31: 1 | L31: Semiurban | M31: Y | N31: Lower Risk
A32: LP001091 | B32: Male | C32: Yes | D32: 1 | E32: Graduate | G32: 4166 | H32: 3369 | I32: 201 | J32: 360 | L32: Urban | M32: N | N32: High Risk
A33: LP001095 | B33: Male | C33: No | D33: 0 | E33: Graduate | F33: No | G33: 3167 | H33: 0 | I33: 74 | J33: 360 | K33: 1 | L33: Urban | M33: N | N33: Medium Risk
A34: LP001097 | B34: Male | C34: No | D34: 1 | E34: Graduate | F34: Yes | G34: 4692 | H34: 0 | I34: 106 | J34: 360 | K34: 1 | L34: Rural | M34: N | N34: Medium Risk
A35: LP001098 | B35: Male | C35: Yes | D35: 0 | E35: Graduate | F35: No | G35: 3500 | H35: 1667 | I35: 114 | J35: 360 | K35: 1 | L35: Semiurban | M35: Y | N35: Lower Risk
A36: LP001100 | B36: Male | C36: No | D36: 3+ | E36: Graduate | F36: No | G36: 12500 | H36: 3000 | I36: 320 | J36: 360 | K36: 1 | L36: Rural | M36: N | N36: Medium Risk
A37: LP001106 | B37: Male | C37: Yes | D37: 0 | E37: Graduate | F37: No | G37: 2275 | H37: 2067 | J37: 360 | K37: 1 | L37: Urban | M37: Y | N37: Lower Risk
A38: LP001109 | B38: Male | C38: Yes | D38: 0 | E38: Graduate | F38: No | G38: 1828 | H38: 1330 | I38: 100 | K38: 0 | L38: Urban | M38: N | N38: High Risk
A39: LP001112 | B39: Female | C39: Yes | D39: 0 | E39: Graduate | F39: No | G39: 3667 | H39: 1459 | I39: 144 | J39: 360 | K39: 1 | L39: Semiurban | M39: Y | N39: Lower Risk
A40: LP001114 | B40: Male | C40: No | D40: 0 | E40: Graduate | F40: No | G40: 4166 | H40: 7210 | I40: 184 | J40: 360 | K40: 1 | L40: Urban | M40: Y | N40: Lower Risk
...

Sheet Data Dictionary
A1: Column Name | B1: Data Type | C1: Description | D1: Missing Values | E1: Unique Values | F1: Comments
A2: Loan_ID | B2: object | C2: Unique loan application identifier | D2: 0 | E2: 614 | F2: Preserved from source workbook
A3: Gender | B3: object | C3: Reported applicant gender category | D3: 13 | E3: 2 | F3: Preserved from source workbook
A4: Married | B4: object | C4: Reported marital status | D4: 3 | E4: 2 | F4: Preserved from source workbook
A5: Dependents | B5: object | C5: Reported dependents category; 3+ is open-ended | D5: 15 | E5: 4 | F5: Preserved from source workbook
A6: Education | B6: object | C6: Education category | D6: 0 | E6: 2 | F6: Preserved from source workbook
A7: Self_Employed | B7: object | C7: Self-employment indicator | D7: 32 | E7: 2 | F7: Preserved from source workbook
A8: ApplicantIncome | B8: int64 | C8: Reported applicant income; unit/period undocumented | D8: 0 | E8: 505 | F8: Preserved from source workbook
A9: CoapplicantIncome | B9: float64 | C9: Reported co-applicant income; unit/period undocumented | D9: 0 | E9: 287 | F9: Preserved from source workbook
A10: LoanAmount | B10: float64 | C10: Requested loan amount; unit undocumented | D10: 22 | E10: 203 | F10: Preserved from source workbook
A11: Loan_Amount_Term | B11: float64 | C11: Reported loan term; unit not explicitly documented | D11: 14 | E11: 10 | F11: Preserved from source workbook
A12: Credit_History | B12: float64 | C12: Recorded credit history indicator | D12: 50 | E12: 2 | F12: Preserved from source workbook
A13: Property_Area | B13: object | C13: Property location category | D13: 0 | E13: 3 | F13: Preserved from source workbook
... A15: Risk_Category | B15: object | C15: Workbook-provided risk category; derivation not documented | D15: 0 | E15: 3 | F15: Preserved from source workbook

Sheet Data Quality
A1: Issue | B1: Affected Field | C1: Count | D1: Percentage | E1: Business Impact | F1: Recommended Action
A2: Missing values | B2: Gender | C2: 13 | D2: 0.021172638 | E2: Incomplete analysis and potentially inconsistent underwriting evidence | F2: Validate and complete from source; do not silently impute
A3: Missing values | B3: Married | C3: 3 | D3: 0.0048859935 | E3: Incomplete analysis and potentially inconsistent underwriting evidence | F3: Validate and complete from source; do not silently impute
A4: Missing values | B4: Dependents | C4: 15 | D4: 0.024429967 | E4: Incomplete analysis and potentially inconsistent underwriting evidence | F4: Validate and complete from source; do not silently impute
A5: Missing values | B5: Self_Employed | C5: 32 | D5: 0.052117264 | E5: Incomplete analysis and potentially inconsistent underwriting evidence | F5: Validate and complete from source; do not silently impute
A6: Missing values | B6: LoanAmount | C6: 22 | D6: 0.035830619 | E6: Incomplete analysis and potentially inconsistent underwriting evidence | F6: Validate and complete from source; do not silently impute
A7: Missing values | B7: Loan_Amount_Term | C7: 14 | D7: 0.022801303 | E7: Incomplete analysis and potentially inconsistent underwriting evidence | F7: Validate and complete from source; do not silently impute
A8: Missing values | B8: Credit_History | C8: 50 | D8: 0.081433225 | E8: Incomplete analysis and potentially inconsistent underwriting evidence | F8: Validate and complete from source; do not silently impute
A9: Duplicate full records | B9: All fields | C9: 0 | D9: 0 | E9: Could overstate portfolio volumes | F9: Investigate and remove only after source confirmation
A10: Duplicate identifiers | B10: Loan_ID | C10: 0 | D10: 0 | E10: Could double-count applications | F10: Enforce unique identifier constraint
A11: IQR outlier flag | B11: ApplicantIncome | C11: 50 | D11: 0.081433225 | E11: May represent valid extremes, input errors or unit issues | F11: Review against source; do not delete automatically
A12: IQR outlier flag | B12: CoapplicantIncome | C12: 18 | D12: 0.029315961 | E12: May represent valid extremes, input errors or unit issues | F12: Review against source; do not delete automatically
A13: IQR outlier flag | B13: LoanAmount | C13: 39 | D13: 0.065878378 | E13: May represent valid extremes, input errors or unit issues | F13: Review against source; do not delete automatically
... A15: Unusual non-positive term | B15: Loan_Amount_Term | C15: 0 | D15: 0 | E15: May invalidate tenor analysis | F15: Verify permitted term values and units

Sheet KPI Summary
A1: KPI | B1: Definition / Formula | C1: Calculated Value | D1: Business Interpretation | E1: Limitation
A2: Total Records | B2: COUNT of application rows | C2: 614 | D2: Applications represented | E2: Not unique customers
A3: Approved Applications | B3: COUNTIF Loan_Status = Y | C3: 422 | D3: Approved decisions | E3: Not disbursements
A4: Rejected Applications | B4: COUNTIF Loan_Status = N | C4: 192 | D4: Rejected decisions | E4: Not defaults
A5: Approval Rate | B5: Approved / Total | C5: 0.68729642 | D5: Decision conversion | E5: Not repayment performance
A6: Rejection Rate | B6: Rejected / Total | C6: 0.31270358 | D6: Non-approval share | E6: Not default rate
A7: Average Applicant Income | B7: AVERAGE ApplicantIncome | C7: 5403.4593 | D7: Reported income profile | E7: Units/period undocumented
A8: Median Applicant Income | B8: MEDIAN ApplicantIncome | C8: 3812.5 | D8: Typical reported income | E8: Units/period undocumented
A9: Average Combined Income | B9: AVERAGE ApplicantIncome + CoapplicantIncome | C9: 7024.7051 | D9: Household-income proxy | E9: Reported, not verified
A10: Average Loan Amount | B10: AVERAGE LoanAmount | C10: 146.41216 | D10: Average requested amount | E10: Unit undocumented
A11: Median Loan Amount | B11: MEDIAN LoanAmount | C11: 128 | D11: Typical requested amount | E11: Missing values excluded
A12: Missing Cell Rate | B12: Missing cells / source cells | C12: 0.017333644 | D12: Overall data completeness | E12: Field-level issues vary

Sheet Numerical Analysis
A1: Field | B1: Count | C1: Missing Count | D1: Mean | E1: Median | F1: Mode | G1: Minimum | H1: Maximum | I1: Range | J1: Variance | K1: Std Dev | L1: Q1 | M1: Q3 | N1: IQR
A2: ApplicantIncome | B2: 614 | C2: 0 | D2: 5403.4593 | E2: 3812.5 | F2: 2500 | G2: 150 | H2: 81000 | I2: 80850 | J2: 37320390 | K2: 6109.0417 | L2: 2877.5 | M2: 5795 | N2: 2917.5
A3: CoapplicantIncome | B3: 614 | C3: 0 | D3: 1621.2458 | E3: 1188.5 | F3: 0 | G3: 0 | H3: 41667 | I3: 41667 | J3: 8562929.5 | K3: 2926.2484 | L3: 0 | M3: 2297.25 | N3: 2297.25
A4: LoanAmount | B4: 592 | C4: 22 | D4: 146.41216 | E4: 128 | F4: 120 | G4: 9 | H4: 700 | I4: 691 | J4: 7325.1902 | K4: 85.587325 | L4: 100 | M4: 168 | N4: 68
A5: Loan_Amount_Term | B5: 600 | C5: 14 | D5: 342 | E5: 360 | F5: 360 | G5: 12 | H5: 480 | I5: 468 | J5: 4240.6678 | K5: 65.12041 | L5: 360 | M5: 360 | N5: 0
A6: Credit_History | B6: 564 | C6: 50 | D6: 0.84219858 | E6: 1 | F6: 1 | G6: 0 | H6: 1 | I6: 1 | J6: 0.13313619 | K6: 0.36487832 | L6: 1 | M6: 1 | N6: 0

Sheet Categorical Analysis
A1: Field | B1: Category | C1: Frequency | D1: Percentage | E1: Rank
A2: Loan_ID | B2: LP002990 | C2: 1 | D2: 0.0016286645 | E2: 1
A3: Loan_ID | B3: LP001002 | C3: 1 | D3: 0.0016286645 | E3: 2
A4: Loan_ID | B4: LP001003 | C4: 1 | D4: 0.0016286645 | E4: 3
A5: Loan_ID | B5: LP001005 | C5: 1 | D5: 0.0016286645 | E5: 4
A6: Loan_ID | B6: LP001006 | C6: 1 | D6: 0.0016286645 | E6: 5
A7: Loan_ID | B7: LP001008 | C7: 1 | D7: 0.0016286645 | E7: 6
A8: Loan_ID | B8: LP002863 | C8: 1 | D8: 0.0016286645 | E8: 7
A9: Loan_ID | B9: LP002868 | C9: 1 | D9: 0.0016286645 | E9: 8
A10: Loan_ID | B10: LP002872 | C10: 1 | D10: 0.0016286645 | E10: 9
A11: Loan_ID | B11: LP002874 | C11: 1 | D11: 0.0016286645 | E11: 10
A12: Loan_ID | B12: LP002877 | C12: 1 | D12: 0.0016286645 | E12: 11
A13: Loan_ID | B13: LP002888 | C13: 1 | D13: 0.0016286645 | E13: 12
... A639: Risk_Category | B639: High Risk | C639: 95 | D639: 0.15472313 | E639: 3

Sheet Correlation Analysis
A1: Variable | B1: ApplicantIncome | C1: CoapplicantIncome | D1: LoanAmount | E1: Loan_Amount_Term | F1: Credit_History | G1: CombinedIncome | H1: Approval_Flag | I1: Loan_to_Income_Index
A2: ApplicantIncome | B2: 1 | C2: -0.11660458 | D2: 0.57090904 | E2: -0.045306087 | F2: -0.014714878 | G2: 0.89303729 | H2: -0.0047095227 | I2: -0.31191765
A3: CoapplicantIncome | B3: -0.11660458 | C3: 1 | D3: 0.1886194 | E3: -0.059878009 | F3: -0.0020562764 | G3: 0.34278082 | H3: -0.059187313 | I3: -0.20632072
A4: LoanAmount | B4: 0.57090904 | C4: 0.1886194 | D4: 1 | E4: 0.039447251 | F4: -0.0084327724 | G4: 0.6246207 | H4: -0.037317769 | I4: 0.16665978
A5: Loan_Amount_Term | B5: -0.045306087 | C5: -0.059878009 | D5: 0.039447251 | E5: 1 | F5: 0.0014701099 | G5: -0.06994841 | H5: -0.021267658 | I5: 0.17797583
A6: Credit_History | B6: -0.014714878 | C6: -0.0020562764 | D6: -0.0084327724 | E6: 0.0014701099 | F6: 1 | G6: -0.015108909 | H6: 0.56167816 | I6: -0.02667831
A7: CombinedIncome | B7: 0.89303729 | C7: 0.34278082 | D7: 0.6246207 | E7: -0.06994841 | F7: -0.015108909 | G7: 1 | H7: -0.031270779 | I7: -0.38819442
A8: Approval_Flag | B8: -0.0047095227 | C8: -0.059187313 | D8: -0.037317769 | E8: -0.021267658 | F8: 0.56167816 | G8: -0.031270779 | H8: 1 | I8: -0.076577457
A9: Loan_to_Income_Index | B9: -0.31191765 | C9: -0.20632072 | D9: 0.16665978 | E9: 0.17797583 | F9: -0.02667831 | G9: -0.38819442 | H9: -0.076577457 | I9: 1

Sheet Trend Analysis
A1: Status | B1: Finding
A2: Unavailable | B2: No date field is present in the application dataset. Monthly, quarterly and yearly trends cannot be calculated without inventing dates.

Sheet Segmentation Analysis
A1: Dimension | B1: Segment | C1: Applications | D1: Approved | E1: Rejected | F1: Approval Rate | G1: Rejection Rate | H1: Sample Flag
A2: Property_Area | B2: Rural | C2: 179 | D2: 110 | E2: 69 | F2: 0.61452514 | G2: 0.38547486
A3: Property_Area | B3: Semiurban | C3: 233 | D3: 179 | E3: 54 | F3: 0.76824034 | G3: 0.23175966
A4: Property_Area | B4: Urban | C4: 202 | D4: 133 | E4: 69 | F4: 0.65841584 | G4: 0.34158416
A5: Credit_History | B5: 0.0 | C5: 89 | D5: 7 | E5: 82 | F5: 0.078651685 | G5: 0.92134831
A6: Credit_History | B6: 1.0 | C6: 475 | D6: 378 | E6: 97 | F6: 0.79578947 | G6: 0.20421053
A7: Credit_History | B7: Missing | C7: 50 | D7: 37 | E7: 13 | F7: 0.74 | G7: 0.26
A8: Education | B8: Graduate | C8: 480 | D8: 340 | E8: 140 | F8: 0.70833333 | G8: 0.29166667
A9: Education | B9: Not Graduate | C9: 134 | D9: 82 | E9: 52 | F9: 0.6119403 | G9: 0.3880597
A10: Self_Employed | B10: No | C10: 500 | D10: 343 | E10: 157 | F10: 0.686 | G10: 0.314
A11: Self_Employed | B11: Yes | C11: 82 | D11: 56 | E11: 26 | F11: 0.68292683 | G11: 0.31707317
A12: Self_Employed | B12: Missing | C12: 32 | D12: 23 | E12: 9 | F12: 0.71875 | G12: 0.28125
A13: Gender | B13: Female | C13: 112 | D13: 75 | E13: 37 | F13: 0.66964286 | G13: 0.33035714
A14: Gender | B14: Male | C14: 489 | D14: 339 | E14: 150 | F14: 0.69325153 | G14: 0.30674847
A15: Gender | B15: Missing | C15: 13 | D15: 8 | E15: 5 | F15: 0.61538462 | G15: 0.38461538 | H15: Small sample
A16: Married | B16: No | C16: 213 | D16: 134 | E16: 79 | F16: 0.62910798 | G16: 0.37089202
A17: Married | B17: Yes | C17: 398 | D17: 285 | E17: 113 | F17: 0.7160804 | G17: 0.2839196
A18: Married | B18: Missing | C18: 3 | D18: 3 | E18: 0 | F18: 1 | G18: 0 | H18: Small sample
A19: Risk_Category | B19: High Risk | C19: 95 | D19: 0 | E19: 95 | F19: 0 | G19: 1
A20: Risk_Category | B20: Lower Risk | C20: 378 | D20: 378 | E20: 0 | F20: 1 | G20: 0
A21: Risk_Category | B21: Medium Risk | C21: 141 | D21: 44 | E21: 97 | F21: 0.31205674 | G21: 0.68794326

Sheet Financial Analysis
A1: Metric | B1: Value | C1: Definition | D1: Interpretation / Limitation
A2: Average Applicant Income | B2: 5403.4593 | C2: Mean ApplicantIncome | D2: Unit and reporting period undocumented
A3: Average Coapplicant Income | B3: 1621.2458 | C3: Mean CoapplicantIncome | D3: Unit and reporting period undocumented
A4: Average Combined Income | B4: 7024.7051 | C4: Mean ApplicantIncome + CoapplicantIncome | D4: Reported, not verified
A5: Median Combined Income | B5: 5416.5 | C5: Median combined reported income | D5: Reported, not verified
A6: Average Loan Amount | B6: 146.41216 | C6: Mean requested LoanAmount | D6: Unit undocumented
A7: Median Loan Amount | B7: 128 | C7: Median requested LoanAmount | D7: Unit undocumented
A8: Median Loan-to-Income Index | B8: 0.024139119 | C8: LoanAmount / CombinedIncome | D8: Relative indicator only; not debt service capacity
A9: Revenue Analysis | B9: Unavailable | C9: No revenue field | D9: Cannot calculate
A10: Cost Analysis | B10: Unavailable | C10: No cost field | D10: Cannot calculate
A11: Credit Exposure | B11: Unavailable | C11: No disbursed or outstanding balance field | D11: Applications are not exposure

Sheet Pivot Tables
A1: Management Summary Tables
A3: Approval outcome by Property_Area
A4: Property_Area | B4: Applications | C4: Approved | D4: Rejected | E4: Approval Rate
A5: Rural | B5: 179 | C5: 110 | D5: 69 | E5: 0.61452514
A6: Semiurban | B6: 233 | C6: 179 | D6: 54 | E6: 0.76824034
A7: Urban | B7: 202 | C7: 133 | D7: 69 | E7: 0.65841584
A20: Approval outcome by Credit_History
A21: Credit_History | B21: Applications | C21: Approved | D21: Rejected | E21: Approval Rate
A22: 0.0 | B22: 89 | C22: 7 | D22: 82 | E22: 0.078651685
A23: 1.0 | B23: 475 | C23: 378 | D23: 97 | E23: 0.79578947
A24: Missing | B24: 50 | C24: 37 | D24: 13 | E24: 0.74
A37: Approval outcome by Education
A38: Education | B38: Applications | C38: Approved | D38: Rejected | E38: Approval Rate
A39: Graduate | B39: 480 | C39: 340 | D39: 140 | E39: 0.70833333
A40: Not Graduate | B40: 134 | C40: 82 | D40: 52 | E40: 0.6119403
A47: Approval outcome by Self_Employed
A48: Self_Employed | B48: Applications | C48: Approved | D48: Rejected | E48: Approval Rate
A49: No | B49: 500 | C49: 343 | D49: 157 | E49: 0.686
A50: Yes | B50: 82 | C50: 56 | D50: 26 | E50: 0.68292683
A51: Missing | B51: 32 | C51: 23 | D51: 9 | E51: 0.71875
A64: Approval outcome by Risk_Category
A65: Risk_Category | B65: Applications | C65: Approved | D65: Rejected | E65: Approval Rate
A66: High Risk | B66: 95 | C66: 0 | D66: 95 | E66: 0
A67: Lower Risk | B67: 378 | C67: 378 | D67: 0 | E67: 1
A68: Medium Risk | B68: 141 | C68: 44 | D68: 97 | E68: 0.31205674
